Workbook

Sheet БазовыеПравила
A1: Рост | B1: Техника | C1: Результативность | D1: Уверенность в отборе (F)
A2: Высокий | B2: Звезда | C2: Высокая | D2: Абсолютная
A3: Высокий | B3: Звезда | C3: Средняя | D3: Абсолютная
A4: Высокий | B4: Звезда | C4: Низкая | D4: Абсолютная
A5: Высокий | B5: Уверенная | C5: Высокая | D5: Абсолютная
A6: Средний | B6: Звезда | C6: Высокая | D6: Абсолютная
A7: Низкий | B7: Звезда | C7: Высокая | D7: Абсолютная
A8: Высокий | B8: Слабая | C8: Средняя | D8: Низкая
A9: Высокий | B9: Слабая | C9: Низкая | D9: Низкая
A10: Средний | B10: Уверенная | C10: Низкая | D10: Низкая
A11: Средний | B11: Слабая | C11: Средняя | D11: Низкая
A12: Средний | B12: Слабая | C12: Низкая | D12: Низкая
... A28: Низкий | B28: Слабая | C28: Высокая | D28: Средняя

Sheet mu-функции
A1: Рост | E1: Низкий | F1: Средний | G1: Высокий | H1: Очень высокий | I1: Нормализованное значение роста | J1: Низкий и Средний (Сумма) | K1: Низкий и Средний (Произведение) | L1: Не низкий
A2: 160 | E2: =1-(A2-160)/25 -> 1 | F2: 0 | G2: 0 | H2: =G2*G2 -> 0 | I2: =(A2-160)/80 -> 0 | J2: =MAX(E2,F2) -> 1 | K2: =MIN(E2,F2) -> 0 | L2: =1-E2 -> 0
A3: 165 | E3: =1-(A3-160)/25 -> 0.8 | F3: 0 | G3: 0 | H3: =G3*G3 -> 0 | I3: =(A3-160)/80 -> 0.0625 | J3: =MAX(E3,F3) -> 0.8 | K3: =MIN(E3,F3) -> 0 | L3: =1-E3 -> 0.2
A4: 170 | E4: =1-(A4-160)/25 -> 0.6 | F4: =IF(A4<=190,(A4-170)/20,(205-A4)/15) -> 0 | G4: 0 | H4: =G4*G4 -> 0 | I4: =(A4-160)/80 -> 0.125 | J4: =MAX(E4,F4) -> 0.6 | K4: =MIN(E4,F4) -> 0 | L4: =1-E4 -> 0.4
A5: 175 | E5: =1-(A5-160)/25 -> 0.4 | F5: =IF(A5<=190,(A5-170)/20,(205-A5)/15) -> 0.25 | G5: 0 | H5: =G5*G5 -> 0 | I5: =(A5-160)/80 -> 0.1875 | J5: =MAX(E5,F5) -> 0.4 | K5: =MIN(E5,F5) -> 0.25 | L5: =1-E5 -> 0.6
A6: 180 | E6: =1-(A6-160)/25 -> 0.2 | F6: =IF(A6<=190,(A6-170)/20,(205-A6)/15) -> 0.5 | G6: 0 | H6: =G6*G6 -> 0 | I6: =(A6-160)/80 -> 0.25 | J6: =MAX(E6,F6) -> 0.5 | K6: =MIN(E6,F6) -> 0.2 | L6: =1-E6 -> 0.8
A7: 185 | E7: =1-(A7-160)/25 -> 0 | F7: =IF(A7<=190,(A7-170)/20,(205-A7)/15) -> 0.75 | G7: 0 | H7: =G7*G7 -> 0 | I7: =(A7-160)/80 -> 0.3125 | J7: =MAX(E7,F7) -> 0.75 | K7: =MIN(E7,F7) -> 0 | L7: =1-E7 -> 1
A8: 190 | E8: 0 | F8: =IF(A8<=190,(A8-170)/20,(205-A8)/15) -> 1 | G8: =(A8-190)/50 -> 0 | H8: =G8*G8 -> 0 | I8: =(A8-160)/80 -> 0.375 | J8: =MAX(E8,F8) -> 1 | K8: =MIN(E8,F8) -> 0 | L8: =1-E8 -> 1
A9: 195 | E9: 0 | F9: =IF(A9<=190,(A9-170)/20,(205-A9)/15) -> 0.66666667 | G9: =(A9-190)/50 -> 0.1 | H9: =G9*G9 -> 0.01 | I9: =(A9-160)/80 -> 0.4375 | J9: =MAX(E9,F9) -> 0.66666667 | K9: =MIN(E9,F9) -> 0 | L9: =1-E9 -> 1
A10: 200 | E10: 0 | F10: =IF(A10<=190,(A10-170)/20,(205-A10)/15) -> 0.33333333 | G10: =(A10-190)/50 -> 0.2 | H10: =G10*G10 -> 0.04 | I10: =(A10-160)/80 -> 0.5 | J10: =MAX(E10,F10) -> 0.33333333 | K10: =MIN(E10,F10) -> 0 | L10: =1-E10 -> 1
A11: 205 | E11: 0 | F11: 0 | G11: =(A11-190)/50 -> 0.3 | H11: =G11*G11 -> 0.09 | I11: =(A11-160)/80 -> 0.5625 | J11: =MAX(E11,F11) -> 0 | K11: =MIN(E11,F11) -> 0 | L11: =1-E11 -> 1
A12: 210 | E12: 0 | F12: 0 | G12: =(A12-190)/50 -> 0.4 | H12: =G12*G12 -> 0.16 | I12: =(A12-160)/80 -> 0.625 | J12: =MAX(E12,F12) -> 0 | K12: =MIN(E12,F12) -> 0 | L12: =1-E12 -> 1
A13: 215 | E13: 0 | F13: 0 | G13: =(A13-190)/50 -> 0.5 | H13: =G13*G13 -> 0.25 | I13: =(A13-160)/80 -> 0.6875 | J13: =MAX(E13,F13) -> 0 | K13: =MIN(E13,F13) -> 0 | L13: =1-E13 -> 1
A14: 220 | E14: 0 | F14: 0 | G14: =(A14-190)/50 -> 0.6 | H14: =G14*G14 -> 0.36 | I14: =(A14-160)/80 -> 0.75 | J14: =MAX(E14,F14) -> 0 | K14: =MIN(E14,F14) -> 0 | L14: =1-E14 -> 1
A15: 225 | E15: 0 | F15: 0 | G15: =(A15-190)/50 -> 0.7 | H15: =G15*G15 -> 0.49 | I15: =(A15-160)/80 -> 0.8125 | J15: =MAX(E15,F15) -> 0 | K15: =MIN(E15,F15) -> 0 | L15: =1-E15 -> 1
A16: 230 | E16: 0 | F16: 0 | G16: =(A16-190)/50 -> 0.8 | H16: =G16*G16 -> 0.64 | I16: =(A16-160)/80 -> 0.875 | J16: =MAX(E16,F16) -> 0 | K16: =MIN(E16,F16) -> 0 | L16: =1-E16 -> 1
A17: 235 | E17: 0 | F17: 0 | G17: =(A17-190)/50 -> 0.9 | H17: =G17*G17 -> 0.81 | I17: =(A17-160)/80 -> 0.9375 | J17: =MAX(E17,F17) -> 0 | K17: =MIN(E17,F17) -> 0 | L17: =1-E17 -> 1
A18: 240 | E18: 0 | F18: 0 | G18: 0.98 | H18: =G18*G18 -> 0.9604 | I18: =(A18-160)/80 -> 1 | J18: =MAX(E18,F18) -> 0 | K18: =MIN(E18,F18) -> 0 | L18: =1-E18 -> 1
B21: = (слабая*1+увереная*2+звезда*3)/3 | C21: = приемлемая^2 | D21: = 1 - очень приемлемая
A22: Техника | B22: Приемлемая техника | C22: Очень приемлемая техника | D22: Не очень приемлемая | E22: Слабая | F22: Уверенная | G22: Звезда | I22: Нормализованное значение техники | J22: Уверенная ИЛИ звезда
A23: 0 | B23: =(E23*1+F23*2+G23*3)/3 -> 0.33333333 | C23: =B23*B23 -> 0.11111111 | D23: =1-C23 -> 0.88888889 | E23: =(40-A23)/40 -> 1 | F23: 0 | G23: 0 | I23: 0
A24: 10 | B24: =(E24*1+F24*2+G24*3)/3 -> 0.25 | C24: =B24*B24 -> 0.0625 | D24: =1-C24 -> 0.9375 | E24: =(40-A24)/40 -> 0.75 | F24: 0 | G24: 0 | I24: 0.1
A25: 20 | B25: =(E25*1+F25*2+G25*3)/3 -> 0.16666667 | C25: =B25*B25 -> 0.027777778 | D25: =1-C25 -> 0.97222222 | E25: =(40-A25)/40 -> 0.5 | F25: =IF(A25<=50,(A25-20)/30,(80-A25)/30) -> 0 | G25: 0 | I25: 0.2
A26: 30 | B26: =(E26*1+F26*2+G26*3)/3 -> 0.30555556 | C26: =B26*B26 -> 0.093364198 | D26: =1-C26 -> 0.9066358 | E26: =(40-A26)/40 -> 0.25 | F26: =IF(A26<=50,(A26-20)/30,(80-A26)/30) -> 0.33333333 | G26: 0 | I26: 0.3
A27: 40 | B27: =(E27*1+F27*2+G27*3)/3 -> 0.44444444 | C27: =B27*B27 -> 0.19753086 | D27: =1-C27 -> 0.80246914 | E27: =(40-A27)/40 -> 0 | F27: =IF(A27<=50,(A27-20)/30,(80-A27)/30) -> 0.66666667 | G27: 0 | I27: 0.4
A28: 50 | B28: =(E28*1+F28*2+G28*3)/3 -> 0.66666667 | C28: =B28*B28 -> 0.44444444 | D28: =1-C28 -> 0.55555556 | E28: 0 | F28: =IF(A28<=50,(A28-20)/30,(80-A28)/30) -> 1 | G28: 0 | I28: 0.5
A29: 60 | B29: =(E29*1+F29*2+G29*3)/3 -> 0.44444444 | C29: =B29*B29 -> 0.19753086 | D29: =1-C29 -> 0.80246914 | E29: 0 | F29: =IF(A29<=50,(A29-20)/30,(80-A29)/30) -> 0.66666667 | G29: 0 | I29: 0.6
A30: 70 | B30: =(E30*1+F30*2+G30*3)/3 -> 0.22222222 | C30: =B30*B30 -> 0.049382716 | D30: =1-C30 -> 0.95061728 | E30: 0 | F30: =IF(A30<=50,(A30-20)/30,(80-A30)/30) -> 0.33333333 | G30: =(A30-70)/30 -> 0 | I30: 0.7
A31: 80 | B31: =(E31*1+F31*2+G31*3)/3 -> 0.33333333 | C31: =B31*B31 -> 0.11111111 | D31: =1-C31 -> 0.88888889 | E31: 0 | F31: =IF(A31<=50,(A31-20)/30,(80-A31)/30) -> 0 | G31: =(A31-70)/30 -> 0.33333333 | I31: 0.8
A32: 90 | B32: =(E32*1+F32*2+G32*3)/3 -> 0.66666667 | C32: =B32*B32 -> 0.44444444 | D32: =1-C32 -> 0.55555556 | E32: 0 | F32: 0 | G32: =(A32-70)/30 -> 0.66666667 | I32: 0.9
A33: 100 | B33: =(E33*1+F33*2+G33*3)/3 -> 1 | C33: =B33*B33 -> 1 | D33: =1-C33 -> 0 | E33: 0 | F33: 0 | G33: =(A33-70)/30 -> 1 | I33: 1
A38: Результативность | E38: Низкая | F38: Средняя | G38: Высокая | I38: Нормализованное значение результативности | J38: Средняя ИЛИ Высокая
A39: 0 | E39: =(20-A39)/20 -> 1 | G39: 0 | I39: 0 | J39: =MAX(F39,G39) -> 0
A40: 5 | E40: =(20-A40)/20 -> 0.75 | G40: 0 | I40: 0.1 | J40: =MAX(F40,G40) -> 0
A41: 10 | E41: =(20-A41)/20 -> 0.5 | F41: =IF(A41<=25,(A41-10)/15,(45-A41)/20) -> 0 | G41: 0 | I41: 0.2 | J41: =MAX(F41,G41) -> 0
A42: 15 | E42: =(20-A42)/20 -> 0.25 | F42: =IF(A42<=25,(A42-10)/15,(45-A42)/20) -> 0.33333333 | G42: 0 | I42: 0.3 | J42: =MAX(F42,G42) -> 0.33333333
A43: 20 | E43: =(20-A43)/20 -> 0 | F43: =IF(A43<=25,(A43-10)/15,(45-A43)/20) -> 0.66666667 | G43: 0 | I43: 0.4 | J43: =MAX(F43,G43) -> 0.66666667
A44: 25 | E44: 0 | F44: =IF(A44<=25,(A44-10)/15,(45-A44)/20) -> 1 | G44: 0 | I44: 0.5 | J44: =MAX(F44,G44) -> 1
A45: 30 | E45: 0 | F45: =IF(A45<=25,(A45-10)/15,(45-A45)/20) -> 0.75 | G45: =(A45-30)/20 -> 0 | I45: 0.6 | J45: =MAX(F45,G45) -> 0.75
A46: 35 | E46: 0 | F46: =IF(A46<=25,(A46-10)/15,(45-A46)/20) -> 0.5 | G46: =(A46-30)/20 -> 0.25 | I46: 0.7 | J46: =MAX(F46,G46) -> 0.5
...

Sheet ОтборИгрока2
A1: ='mu-функции'!A1 -> Рост | B1: ='mu-функции'!E1 -> Низкий | C1: ='mu-функции'!F1 -> Средний | D1: ='mu-функции'!G1 -> Высокий | E1: ='mu-функции'!I1 -> Нормализованное значение роста | G1: ='mu-функции'!A22 -> Техника | H1: ='mu-функции'!E22 -> Слабая | I1: ='mu-функции'!F22 -> Уверенная | J1: ='mu-функции'!G22 -> Звезда | K1: ='mu-функции'!I22 -> Нормализованное значение техники | M1: ='mu-функции'!E38 -> Низкая | N1: ='mu-функции'!F38 -> Средняя | O1: ='mu-функции'!G38 -> Высокая | P1: ='mu-функции'!I38 -> Нормализованное значение результативности | R1: Функции отбора | S1: Абсолютная | T1: Средняя | U1: Низкая | V1: Отказ
A2: ='mu-функции'!A2 -> 160 | B2: ='mu-функции'!E2 -> 1 | C2: ='mu-функции'!F2 -> 0 | D2: ='mu-функции'!G2 -> 0 | E2: ='mu-функции'!I2 -> 0 | G2: ='mu-функции'!A23 -> 0 | H2: ='mu-функции'!E23 -> 1 | I2: ='mu-функции'!F23 -> 0 | J2: ='mu-функции'!G23 -> 0 | K2: ='mu-функции'!I23 -> 0 | M2: ='mu-функции'!E39 -> 1 | N2: ='mu-функции'!F39 -> 0 | O2: ='mu-функции'!G39 -> 0 | P2: ='mu-функции'!I39 -> 0 | S2: =IF(OR(AND(J2>0,D2>0), AND(D2>0,I2>0,O2>0)), MAX(MAX(I2,J2),D2,O2),0) -> 0
A3: ='mu-функции'!A3 -> 165 | B3: ='mu-функции'!E3 -> 0.8 | C3: ='mu-функции'!F3 -> 0 | D3: ='mu-функции'!G3 -> 0 | E3: ='mu-функции'!I3 -> 0.0625 | G3: ='mu-функции'!A24 -> 10 | H3: ='mu-функции'!E24 -> 0.75 | I3: ='mu-функции'!F24 -> 0 | J3: ='mu-функции'!G24 -> 0 | K3: ='mu-функции'!I24 -> 0.1 | M3: ='mu-функции'!E40 -> 0.75 | N3: ='mu-функции'!F40 -> 0 | O3: ='mu-функции'!G40 -> 0 | P3: ='mu-функции'!I40 -> 0.1 | S3: =IF(OR(AND(J3>0,D3>0), AND(D3>0,I3>0,O3>0)), MAX(MAX(I3,J3),D3,O3),0) -> 0
A4: ='mu-функции'!A4 -> 170 | B4: ='mu-функции'!E4 -> 0.6 | C4: ='mu-функции'!F4 -> 0 | D4: ='mu-функции'!G4 -> 0 | E4: ='mu-функции'!I4 -> 0.125 | G4: ='mu-функции'!A25 -> 20 | H4: ='mu-функции'!E25 -> 0.5 | I4: ='mu-функции'!F25 -> 0 | J4: ='mu-функции'!G25 -> 0 | K4: ='mu-функции'!I25 -> 0.2 | M4: ='mu-функции'!E41 -> 0.5 | N4: ='mu-функции'!F41 -> 0 | O4: ='mu-функции'!G41 -> 0 | P4: ='mu-функции'!I41 -> 0.2 | S4: =IF(OR(AND(J4>0,D4>0), AND(D4>0,I4>0,O4>0)), MAX(MAX(I4,J4),D4,O4),0) -> 0
A5: ='mu-функции'!A5 -> 175 | B5: ='mu-функции'!E5 -> 0.4 | C5: ='mu-функции'!F5 -> 0.25 | D5: ='mu-функции'!G5 -> 0 | E5: ='mu-функции'!I5 -> 0.1875 | G5: ='mu-функции'!A26 -> 30 | H5: ='mu-функции'!E26 -> 0.25 | I5: ='mu-функции'!F26 -> 0.33333333 | J5: ='mu-функции'!G26 -> 0 | K5: ='mu-функции'!I26 -> 0.3 | M5: ='mu-функции'!E42 -> 0.25 | N5: ='mu-функции'!F42 -> 0.33333333 | O5: ='mu-функции'!G42 -> 0 | P5: ='mu-функции'!I42 -> 0.3 | S5: =IF(OR(AND(J5>0,D5>0), AND(D5>0,I5>0,O5>0)), MAX(MAX(I5,J5),D5,O5),0) -> 0
A6: ='mu-функции'!A6 -> 180 | B6: ='mu-функции'!E6 -> 0.2 | C6: ='mu-функции'!F6 -> 0.5 | D6: ='mu-функции'!G6 -> 0 | E6: ='mu-функции'!I6 -> 0.25 | G6: ='mu-функции'!A27 -> 40 | H6: ='mu-функции'!E27 -> 0 | I6: ='mu-функции'!F27 -> 0.66666667 | J6: ='mu-функции'!G27 -> 0 | K6: ='mu-функции'!I27 -> 0.4 | M6: ='mu-функции'!E43 -> 0 | N6: ='mu-функции'!F43 -> 0.66666667 | O6: ='mu-функции'!G43 -> 0 | P6: ='mu-функции'!I43 -> 0.4 | S6: =IF(OR(AND(J6>0,D6>0), AND(D6>0,I6>0,O6>0)), MAX(MAX(I6,J6),D6,O6),0) -> 0
A7: ='mu-функции'!A7 -> 185 | B7: ='mu-функции'!E7 -> 0 | C7: ='mu-функции'!F7 -> 0.75 | D7: ='mu-функции'!G7 -> 0 | E7: ='mu-функции'!I7 -> 0.3125 | G7: ='mu-функции'!A28 -> 50 | H7: ='mu-функции'!E28 -> 0 | I7: ='mu-функции'!F28 -> 1 | J7: ='mu-функции'!G28 -> 0 | K7: ='mu-функции'!I28 -> 0.5 | M7: ='mu-функции'!E44 -> 0 | N7: ='mu-функции'!F44 -> 1 | O7: ='mu-функции'!G44 -> 0 | P7: ='mu-функции'!I44 -> 0.5 | S7: =IF(OR(AND(J7>0,D7>0), AND(D7>0,I7>0,O7>0)), MAX(MAX(I7,J7),D7,O7),0) -> 0
A8: ='mu-функции'!A8 -> 190 | B8: ='mu-функции'!E8 -> 0 | C8: ='mu-функции'!F8 -> 1 | D8: ='mu-функции'!G8 -> 0 | E8: ='mu-функции'!I8 -> 0.375 | G8: ='mu-функции'!A29 -> 60 | H8: ='mu-функции'!E29 -> 0 | I8: ='mu-функции'!F29 -> 0.66666667 | J8: ='mu-функции'!G29 -> 0 | K8: ='mu-функции'!I29 -> 0.6 | M8: ='mu-функции'!E45 -> 0 | N8: ='mu-функции'!F45 -> 0.75 | O8: ='mu-функции'!G45 -> 0 | P8: ='mu-функции'!I45 -> 0.6 | S8: =IF(OR(AND(J8>0,D8>0), AND(D8>0,I8>0,O8>0)), MAX(MAX(I8,J8),D8,O8),0) -> 0
A9: ='mu-функции'!A9 -> 195 | B9: ='mu-функции'!E9 -> 0 | C9: ='mu-функции'!F9 -> 0.66666667 | D9: ='mu-функции'!G9 -> 0.1 | E9: ='mu-функции'!I9 -> 0.4375 | G9: ='mu-функции'!A30 -> 70 | H9: ='mu-функции'!E30 -> 0 | I9: ='mu-функции'!F30 -> 0.33333333 | J9: ='mu-функции'!G30 -> 0 | K9: ='mu-функции'!I30 -> 0.7 | M9: ='mu-функции'!E46 -> 0 | N9: ='mu-функции'!F46 -> 0.5 | O9: ='mu-функции'!G46 -> 0.25 | P9: ='mu-функции'!I46 -> 0.7 | S9: =IF(OR(AND(J9>0,D9>0), AND(D9>0,I9>0,O9>0)), MAX(MAX(I9,J9),D9,O9),0) -> 0.33333333
A10: ='mu-функции'!A10 -> 200 | B10: ='mu-функции'!E10 -> 0 | C10: ='mu-функции'!F10 -> 0.33333333 | D10: ='mu-функции'!G10 -> 0.2 | E10: ='mu-функции'!I10 -> 0.5 | G10: ='mu-функции'!A31 -> 80 | H10: ='mu-функции'!E31 -> 0 | I10: ='mu-функции'!F31 -> 0 | J10: ='mu-функции'!G31 -> 0.33333333 | K10: ='mu-функции'!I31 -> 0.8 | M10: ='mu-функции'!E47 -> 0 | N10: ='mu-функции'!F47 -> 0.25 | O10: ='mu-функции'!G47 -> 0.5 | P10: ='mu-функции'!I47 -> 0.8 | S10: =IF(OR(AND(J10>0,D10>0), AND(D10>0,I10>0,O10>0)), MAX(MAX(I10,J10),D10,O10),0) -> 0.5
A11: ='mu-функции'!A11 -> 205 | B11: ='mu-функции'!E11 -> 0 | C11: ='mu-функции'!F11 -> 0 | D11: ='mu-функции'!G11 -> 0.3 | E11: ='mu-функции'!I11 -> 0.5625 | G11: ='mu-функции'!A32 -> 90 | H11: ='mu-функции'!E32 -> 0 | I11: ='mu-функции'!F32 -> 0 | J11: ='mu-функции'!G32 -> 0.66666667 | K11: ='mu-функции'!I32 -> 0.9 | M11: ='mu-функции'!E48 -> 0 | N11: ='mu-функции'!F48 -> 0 | O11: ='mu-функции'!G48 -> 0.75 | P11: ='mu-функции'!I48 -> 0.9 | S11: =IF(OR(AND(J11>0,D11>0), AND(D11>0,I11>0,O11>0)), MAX(MAX(I11,J11),D11,O11),0) -> 0.75
A12: ='mu-функции'!A12 -> 210 | B12: ='mu-функции'!E12 -> 0 | C12: ='mu-функции'!F12 -> 0 | D12: ='mu-функции'!G12 -> 0.4 | E12: ='mu-функции'!I12 -> 0.625 | G12: ='mu-функции'!A33 -> 100 | H12: ='mu-функции'!E33 -> 0 | I12: ='mu-функции'!F33 -> 0 | J12: ='mu-функции'!G33 -> 1 | K12: ='mu-функции'!I33 -> 1 | M12: ='mu-функции'!E49 -> 0 | N12: ='mu-функции'!F49 -> 0 | O12: ='mu-функции'!G49 -> 1 | P12: ='mu-функции'!I49 -> 1 | S12: =IF(OR(AND(J12>0,D12>0), AND(D12>0,I12>0,O12>0)), MAX(MAX(I12,J12),D12,O12),0) -> 1
A13: ='mu-функции'!A13 -> 215 | B13: ='mu-функции'!E13 -> 0 | C13: ='mu-функции'!F13 -> 0 | D13: ='mu-функции'!G13 -> 0.5 | E13: ='mu-функции'!I13 -> 0.6875
A14: ='mu-функции'!A14 -> 220 | B14: ='mu-функции'!E14 -> 0 | C14: ='mu-функции'!F14 -> 0 | D14: ='mu-функции'!G14 -> 0.6 | E14: ='mu-функции'!I14 -> 0.75
A15: ='mu-функции'!A15 -> 225 | B15: ='mu-функции'!E15 -> 0 | C15: ='mu-функции'!F15 -> 0 | D15: ='mu-функции'!G15 -> 0.7 | E15: ='mu-функции'!I15 -> 0.8125
A16: ='mu-функции'!A16 -> 230 | B16: ='mu-функции'!E16 -> 0 | C16: ='mu-функции'!F16 -> 0 | D16: ='mu-функции'!G16 -> 0.8 | E16: ='mu-функции'!I16 -> 0.875
A17: ='mu-функции'!A17 -> 235 | B17: ='mu-функции'!E17 -> 0 | C17: ='mu-функции'!F17 -> 0 | D17: ='mu-функции'!G17 -> 0.9 | E17: ='mu-функции'!I17 -> 0.9375
A18: ='mu-функции'!A18 -> 240 | B18: ='mu-функции'!E18 -> 0 | C18: ='mu-функции'!F18 -> 0 | D18: ='mu-функции'!G18 -> 0.98 | E18: ='mu-функции'!I18 -> 1

Sheet Расчет кандидатовВ1
A1: Кандидат | B1: Рост | C1: Техника | D1: Результативность | E1: Решение/Уверенность | F1: Расчетный результат Рост | G1: Расчетный результат Техника | H1: Расчетный Результативность
A2: А | B2: 165 | C2: 20 | D2: 10 | E2: Отказ | F2: Низкий | G2: Слабая | H2: Низкая
A3: Б | B3: 180 | C3: 50 | D3: 50 | E3: Средняя | F3: Низкий | G3: Уверенная | H3: Высокая
A4: В | B4: 200 | C4: 80 | D4: 25 | E4: Средняя | F4: Средний | G4: Звезда | H4: Средняя
A5: Г | B5: 160 | C5: 80 | D5: 45 | E5: Абсолютная | F5: Низкий | G5: Звезда | H5: Высокая
A6: Д | B6: 245 | C6: 10 | D6: 35 | E6: Низкая | F6: Высокий | G6: Слабая | H6: Средняя
A7: Е | B7: 250 | C7: 90 | D7: 45 | E7: Абсолютная | F7: Высокий | G7: Звезда | H7: Высокая

Sheet Лист1
A1: Рост | B1: Низкий (B) | C1: Низкий2 (A)
A2: 160 | B2: 1 | C2: 1
A3: 165 | B3: 0.8 | C3: 0.8
A4: 170 | B4: 0.6 | C4: 0.6
A5: 175 | B5: 0.4 | C5: 0.5
A6: 180 | B6: 0.2 | C6: 0 | D6: 0.8
A7: 185 | B7: 0 | C7: 0
A8: 190 | B8: 0 | C8: 0
A9: 195 | B9: 0 | C9: 0
A10: 200 | B10: 0 | C10: 0
A11: 205 | B11: 0 | C11: 0
A12: 210 | B12: 0 | C12: 0
A13: 215 | B13: 0 | C13: 0
A14: 220 | B14: 0 | C14: 0
A15: 225 | B15: 0 | C15: 0
A16: 230 | B16: 0 | C16: 0
A17: 235 | B17: 0 | C17: 0
A18: 240 | B18: 0 | C18: 0
