Workbook

Sheet БазовыеПравила
A1: Рост | B1: Техника | C1: Результативность | D1: Уверенность в отборе (F)
A2: Высокий | B2: Звезда | C2: Высокая | D2: Абсолютная
A3: Высокий | B3: Звезда | C3: Средняя | D3: Абсолютная
A4: Высокий | B4: Звезда | C4: Низкая | D4: Абсолютная
A5: Высокий | B5: Уверенная | C5: Высокая | D5: Абсолютная
A6: Средний | B6: Звезда | C6: Высокая | D6: Абсолютная
A7: Низкий | B7: Звезда | C7: Высокая | D7: Абсолютная
A8: Высокий | B8: Слабая | C8: Средняя | D8: Низкая
A9: Высокий | B9: Слабая | C9: Низкая | D9: Низкая
A10: Средний | B10: Уверенная | C10: Низкая | D10: Низкая
A11: Средний | B11: Слабая | C11: Средняя | D11: Низкая
A12: Средний | B12: Слабая | C12: Низкая | D12: Низкая
... A28: Низкий | B28: Слабая | C28: Высокая | D28: Средняя

Sheet mu-функции
A1: Рост | B1: Низкий | C1: Средний | D1: Высокий | E1: Очень высокий | F1: Нормализованное значение роста | G1: Низкий и Средний (Сумма) | H1: Низкий и Средний (Произведение) | I1: Не низкий | J1: Среднего и Высокого
A2: 160 | B2: =1-(A2-160)/25 -> 1 | C2: 0 | D2: 0 | E2: =D2*D2 -> 0 | F2: =(A2-160)/80 -> 0 | G2: =MAX(B2,C2) -> 1 | H2: =MIN(B2,C2) -> 0 | I2: =1-B2 -> 0 | J2: =MIN(C2,D2) -> 0
A3: 165 | B3: =1-(A3-160)/25 -> 0.8 | C3: 0 | D3: 0 | E3: =D3*D3 -> 0 | F3: =(A3-160)/80 -> 0.0625 | G3: =MAX(B3,C3) -> 0.8 | H3: =MIN(B3,C3) -> 0 | I3: =1-B3 -> 0.2 | J3: =MIN(C3,D3) -> 0
A4: 170 | B4: =1-(A4-160)/25 -> 0.6 | C4: =IF(A4<=190,(A4-170)/20,(205-A4)/15) -> 0 | D4: 0 | E4: =D4*D4 -> 0 | F4: =(A4-160)/80 -> 0.125 | G4: =MAX(B4,C4) -> 0.6 | H4: =MIN(B4,C4) -> 0 | I4: =1-B4 -> 0.4 | J4: =MIN(C4,D4) -> 0
A5: 175 | B5: =1-(A5-160)/25 -> 0.4 | C5: =IF(A5<=190,(A5-170)/20,(205-A5)/15) -> 0.25 | D5: 0 | E5: =D5*D5 -> 0 | F5: =(A5-160)/80 -> 0.1875 | G5: =MAX(B5,C5) -> 0.4 | H5: =MIN(B5,C5) -> 0.25 | I5: =1-B5 -> 0.6 | J5: =MIN(C5,D5) -> 0
A6: 180 | B6: =1-(A6-160)/25 -> 0.2 | C6: =IF(A6<=190,(A6-170)/20,(205-A6)/15) -> 0.5 | D6: 0 | E6: =D6*D6 -> 0 | F6: =(A6-160)/80 -> 0.25 | G6: =MAX(B6,C6) -> 0.5 | H6: =MIN(B6,C6) -> 0.2 | I6: =1-B6 -> 0.8 | J6: =MIN(C6,D6) -> 0
A7: 185 | B7: =1-(A7-160)/25 -> 0 | C7: =IF(A7<=190,(A7-170)/20,(205-A7)/15) -> 0.75 | D7: 0 | E7: =D7*D7 -> 0 | F7: =(A7-160)/80 -> 0.3125 | G7: =MAX(B7,C7) -> 0.75 | H7: =MIN(B7,C7) -> 0 | I7: =1-B7 -> 1 | J7: =MIN(C7,D7) -> 0
A8: 190 | B8: 0 | C8: =IF(A8<=190,(A8-170)/20,(205-A8)/15) -> 1 | D8: =(A8-190)/50 -> 0 | E8: =D8*D8 -> 0 | F8: =(A8-160)/80 -> 0.375 | G8: =MAX(B8,C8) -> 1 | H8: =MIN(B8,C8) -> 0 | I8: =1-B8 -> 1 | J8: =MIN(C8,D8) -> 0
A9: 195 | B9: 0 | C9: =IF(A9<=190,(A9-170)/20,(205-A9)/15) -> 0.66666667 | D9: =(A9-190)/50 -> 0.1 | E9: =D9*D9 -> 0.01 | F9: =(A9-160)/80 -> 0.4375 | G9: =MAX(B9,C9) -> 0.66666667 | H9: =MIN(B9,C9) -> 0 | I9: =1-B9 -> 1 | J9: =MIN(C9,D9) -> 0.1
A10: 200 | B10: 0 | C10: =IF(A10<=190,(A10-170)/20,(205-A10)/15) -> 0.33333333 | D10: =(A10-190)/50 -> 0.2 | E10: =D10*D10 -> 0.04 | F10: =(A10-160)/80 -> 0.5 | G10: =MAX(B10,C10) -> 0.33333333 | H10: =MIN(B10,C10) -> 0 | I10: =1-B10 -> 1 | J10: =MIN(C10,D10) -> 0.2
A11: 205 | B11: 0 | C11: 0 | D11: =(A11-190)/50 -> 0.3 | E11: =D11*D11 -> 0.09 | F11: =(A11-160)/80 -> 0.5625 | G11: =MAX(B11,C11) -> 0 | H11: =MIN(B11,C11) -> 0 | I11: =1-B11 -> 1 | J11: =MIN(C11,D11) -> 0
A12: 210 | B12: 0 | C12: 0 | D12: =(A12-190)/50 -> 0.4 | E12: =D12*D12 -> 0.16 | F12: =(A12-160)/80 -> 0.625 | G12: =MAX(B12,C12) -> 0 | H12: =MIN(B12,C12) -> 0 | I12: =1-B12 -> 1 | J12: =MIN(C12,D12) -> 0
A13: 215 | B13: 0 | C13: 0 | D13: =(A13-190)/50 -> 0.5 | E13: =D13*D13 -> 0.25 | F13: =(A13-160)/80 -> 0.6875 | G13: =MAX(B13,C13) -> 0 | H13: =MIN(B13,C13) -> 0 | I13: =1-B13 -> 1 | J13: =MIN(C13,D13) -> 0
A14: 220 | B14: 0 | C14: 0 | D14: =(A14-190)/50 -> 0.6 | E14: =D14*D14 -> 0.36 | F14: =(A14-160)/80 -> 0.75 | G14: =MAX(B14,C14) -> 0 | H14: =MIN(B14,C14) -> 0 | I14: =1-B14 -> 1 | J14: =MIN(C14,D14) -> 0
A15: 225 | B15: 0 | C15: 0 | D15: =(A15-190)/50 -> 0.7 | E15: =D15*D15 -> 0.49 | F15: =(A15-160)/80 -> 0.8125 | G15: =MAX(B15,C15) -> 0 | H15: =MIN(B15,C15) -> 0 | I15: =1-B15 -> 1 | J15: =MIN(C15,D15) -> 0
A16: 230 | B16: 0 | C16: 0 | D16: =(A16-190)/50 -> 0.8 | E16: =D16*D16 -> 0.64 | F16: =(A16-160)/80 -> 0.875 | G16: =MAX(B16,C16) -> 0 | H16: =MIN(B16,C16) -> 0 | I16: =1-B16 -> 1 | J16: =MIN(C16,D16) -> 0
A17: 235 | B17: 0 | C17: 0 | D17: =(A17-190)/50 -> 0.9 | E17: =D17*D17 -> 0.81 | F17: =(A17-160)/80 -> 0.9375 | G17: =MAX(B17,C17) -> 0 | H17: =MIN(B17,C17) -> 0 | I17: =1-B17 -> 1 | J17: =MIN(C17,D17) -> 0
A18: 240 | B18: 0 | C18: 0 | D18: 0.98 | E18: =D18*D18 -> 0.9604 | F18: =(A18-160)/80 -> 1 | G18: =MAX(B18,C18) -> 0 | H18: =MIN(B18,C18) -> 0 | I18: =1-B18 -> 1 | J18: =MIN(C18,D18) -> 0
A22: Техника | B22: Слабая | C22: Уверенная | D22: Звезда | F22: Нормализованное значение техники | G22: Уверенная ИЛИ звезда
A23: 0 | B23: =(40-A23)/40 -> 1 | C23: 0 | D23: 0 | F23: 0 | G23: =MAX(C23:D23) -> 0
A24: 10 | B24: =(40-A24)/40 -> 0.75 | C24: 0 | D24: 0 | F24: 0.1 | G24: =MAX(C24:D24) -> 0
A25: 20 | B25: =(40-A25)/40 -> 0.5 | C25: =IF(A25<=50,(A25-20)/30,(80-A25)/30) -> 0 | D25: 0 | F25: 0.2 | G25: =MAX(C25:D25) -> 0
A26: 30 | B26: =(40-A26)/40 -> 0.25 | C26: =IF(A26<=50,(A26-20)/30,(80-A26)/30) -> 0.33333333 | D26: 0 | F26: 0.3 | G26: =MAX(C26:D26) -> 0.33333333
A27: 40 | B27: =(40-A27)/40 -> 0 | C27: =IF(A27<=50,(A27-20)/30,(80-A27)/30) -> 0.66666667 | D27: 0 | F27: 0.4 | G27: =MAX(C27:D27) -> 0.66666667
A28: 50 | B28: 0 | C28: =IF(A28<=50,(A28-20)/30,(80-A28)/30) -> 1 | D28: 0 | F28: 0.5 | G28: =MAX(C28:D28) -> 1
A29: 60 | B29: 0 | C29: =IF(A29<=50,(A29-20)/30,(80-A29)/30) -> 0.66666667 | D29: 0 | F29: 0.6 | G29: =MAX(C29:D29) -> 0.66666667
A30: 70 | B30: 0 | C30: =IF(A30<=50,(A30-20)/30,(80-A30)/30) -> 0.33333333 | D30: =(A30-70)/30 -> 0 | F30: 0.7 | G30: =MAX(C30:D30) -> 0.33333333
A31: 80 | B31: 0 | C31: =IF(A31<=50,(A31-20)/30,(80-A31)/30) -> 0 | D31: =(A31-70)/30 -> 0.33333333 | F31: 0.8 | G31: =MAX(C31:D31) -> 0.33333333
A32: 90 | B32: 0 | C32: 0 | D32: =(A32-70)/30 -> 0.66666667 | F32: 0.9 | G32: =MAX(C32:D32) -> 0.66666667
A33: 100 | B33: 0 | C33: 0 | D33: =(A33-70)/30 -> 1 | F33: 1 | G33: =MAX(C33:D33) -> 1
A38: Результативность | B38: Низкая | C38: Средняя | D38: Высокая | F38: Нормализованное значение результативности | G38: Средняя ИЛИ Высокая
A39: 0 | B39: =(20-A39)/20 -> 1 | D39: 0 | F39: 0 | G39: =MAX(C39,D39) -> 0
A40: 5 | B40: =(20-A40)/20 -> 0.75 | D40: 0 | F40: 0.1 | G40: =MAX(C40,D40) -> 0
A41: 10 | B41: =(20-A41)/20 -> 0.5 | C41: =IF(A41<=25,(A41-10)/15,(45-A41)/20) -> 0 | D41: 0 | F41: 0.2 | G41: =MAX(C41,D41) -> 0
A42: 15 | B42: =(20-A42)/20 -> 0.25 | C42: =IF(A42<=25,(A42-10)/15,(45-A42)/20) -> 0.33333333 | D42: 0 | F42: 0.3 | G42: =MAX(C42,D42) -> 0.33333333
A43: 20 | B43: =(20-A43)/20 -> 0 | C43: =IF(A43<=25,(A43-10)/15,(45-A43)/20) -> 0.66666667 | D43: 0 | F43: 0.4 | G43: =MAX(C43,D43) -> 0.66666667
A44: 25 | B44: 0 | C44: =IF(A44<=25,(A44-10)/15,(45-A44)/20) -> 1 | D44: 0 | F44: 0.5 | G44: =MAX(C44,D44) -> 1
A45: 30 | B45: 0 | C45: =IF(A45<=25,(A45-10)/15,(45-A45)/20) -> 0.75 | D45: =(A45-30)/20 -> 0 | F45: 0.6 | G45: =MAX(C45,D45) -> 0.75
A46: 35 | B46: 0 | C46: =IF(A46<=25,(A46-10)/15,(45-A46)/20) -> 0.5 | D46: =(A46-30)/20 -> 0.25 | F46: 0.7 | G46: =MAX(C46,D46) -> 0.5
A47: 40 | B47: 0 | C47: =IF(A47<=25,(A47-10)/15,(45-A47)/20) -> 0.25 | D47: =(A47-30)/20 -> 0.5 | F47: 0.8 | G47: =MAX(C47,D47) -> 0.5
...

Sheet ОтборИгрока2
A1: ='mu-функции'!A1 -> Рост | B1: ='mu-функции'!B1 -> Низкий | C1: ='mu-функции'!C1 -> Средний | D1: ='mu-функции'!D1 -> Высокий | E1: ='mu-функции'!F1 -> Нормализованное значение роста | G1: ='mu-функции'!A22 -> Техника | H1: ='mu-функции'!B22 -> Слабая | I1: ='mu-функции'!C22 -> Уверенная | J1: ='mu-функции'!D22 -> Звезда | K1: ='mu-функции'!F22 -> Нормализованное значение техники | M1: ='mu-функции'!B38 -> Низкая | N1: ='mu-функции'!C38 -> Средняя | O1: ='mu-функции'!D38 -> Высокая | P1: ='mu-функции'!F38 -> Нормализованное значение результативности | R1: Функции отбора | S1: Абсолютная | T1: Средняя | U1: Низкая | V1: Отказ | W1: Постусловие(принять/отказать)
A2: ='mu-функции'!A2 -> 160 | B2: ='mu-функции'!B2 -> 1 | C2: ='mu-функции'!C2 -> 0 | D2: ='mu-функции'!D2 -> 0 | E2: ='mu-функции'!F2 -> 0 | G2: ='mu-функции'!A23 -> 0 | H2: ='mu-функции'!B23 -> 1 | I2: ='mu-функции'!C23 -> 0 | J2: ='mu-функции'!D23 -> 0 | K2: ='mu-функции'!F23 -> 0 | M2: ='mu-функции'!B39 -> 1 | N2: ='mu-функции'!C39 -> 0 | O2: ='mu-функции'!D39 -> 0 | P2: ='mu-функции'!F39 -> 0 | S2: =IF(OR(AND(J2>0,D2>0), AND(D2>0,I2>0,O2>0)), MAX(MAX(I2,J2),D2,O2),0) -> 0 | T2: =MAX(V2) -> 0 | U2: =MIN(C2,MIN(MIN(G2,H2),M2,N2)) -> 0 | W2: =IF(OR(S2>U2,T2>U2),"принять","отказать") -> отказать
A3: ='mu-функции'!A3 -> 165 | B3: ='mu-функции'!B3 -> 0.8 | C3: ='mu-функции'!C3 -> 0 | D3: ='mu-функции'!D3 -> 0 | E3: ='mu-функции'!F3 -> 0.0625 | G3: ='mu-функции'!A24 -> 10 | H3: ='mu-функции'!B24 -> 0.75 | I3: ='mu-функции'!C24 -> 0 | J3: ='mu-функции'!D24 -> 0 | K3: ='mu-функции'!F24 -> 0.1 | M3: ='mu-функции'!B40 -> 0.75 | N3: ='mu-функции'!C40 -> 0 | O3: ='mu-функции'!D40 -> 0 | P3: ='mu-функции'!F40 -> 0.1 | S3: =IF(OR(AND(J3>0,D3>0), AND(D3>0,I3>0,O3>0)), MAX(MAX(I3,J3),D3,O3),0) -> 0 | T3: =MAX(MIN(MAX(C3,D3),MAX(H3,I3)),MIN(N3,O3)) -> 0 | U3: =MIN(C3,MIN(MIN(G3,H3),M3,N3)) -> 0 | W3: =IF(OR(S3>U3,T3>U3),"принять","отказать") -> отказать
A4: ='mu-функции'!A4 -> 170 | B4: ='mu-функции'!B4 -> 0.6 | C4: ='mu-функции'!C4 -> 0 | D4: ='mu-функции'!D4 -> 0 | E4: ='mu-функции'!F4 -> 0.125 | G4: ='mu-функции'!A25 -> 20 | H4: ='mu-функции'!B25 -> 0.5 | I4: ='mu-функции'!C25 -> 0 | J4: ='mu-функции'!D25 -> 0 | K4: ='mu-функции'!F25 -> 0.2 | M4: ='mu-функции'!B41 -> 0.5 | N4: ='mu-функции'!C41 -> 0 | O4: ='mu-функции'!D41 -> 0 | P4: ='mu-функции'!F41 -> 0.2 | S4: =IF(OR(AND(J4>0,D4>0), AND(D4>0,I4>0,O4>0)), MAX(MAX(I4,J4),D4,O4),0) -> 0 | T4: =MAX(MIN(MAX(C4,D4),MAX(H4,I4)),MIN(N4,O4)) -> 0 | U4: =MIN(C4,MIN(MIN(G4,H4),M4,N4)) -> 0 | W4: =IF(OR(S4>U4,T4>U4),"принять","отказать") -> отказать
A5: ='mu-функции'!A5 -> 175 | B5: ='mu-функции'!B5 -> 0.4 | C5: ='mu-функции'!C5 -> 0.25 | D5: ='mu-функции'!D5 -> 0 | E5: ='mu-функции'!F5 -> 0.1875 | G5: ='mu-функции'!A26 -> 30 | H5: ='mu-функции'!B26 -> 0.25 | I5: ='mu-функции'!C26 -> 0.33333333 | J5: ='mu-функции'!D26 -> 0 | K5: ='mu-функции'!F26 -> 0.3 | M5: ='mu-функции'!B42 -> 0.25 | N5: ='mu-функции'!C42 -> 0.33333333 | O5: ='mu-функции'!D42 -> 0 | P5: ='mu-функции'!F42 -> 0.3 | S5: =IF(OR(AND(J5>0,D5>0), AND(D5>0,I5>0,O5>0)), MAX(MAX(I5,J5),D5,O5),0) -> 0 | T5: =MAX(MIN(MAX(C5,D5),MAX(H5,I5)),MIN(N5,O5)) -> 0.25 | U5: =MIN(C5,MIN(MIN(G5,H5),M5,N5)) -> 0.25 | W5: =IF(OR(S5>U5,T5>U5),"принять","отказать") -> отказать
A6: ='mu-функции'!A6 -> 180 | B6: ='mu-функции'!B6 -> 0.2 | C6: ='mu-функции'!C6 -> 0.5 | D6: ='mu-функции'!D6 -> 0 | E6: ='mu-функции'!F6 -> 0.25 | G6: ='mu-функции'!A27 -> 40 | H6: ='mu-функции'!B27 -> 0 | I6: ='mu-функции'!C27 -> 0.66666667 | J6: ='mu-функции'!D27 -> 0 | K6: ='mu-функции'!F27 -> 0.4 | M6: ='mu-функции'!B43 -> 0 | N6: ='mu-функции'!C43 -> 0.66666667 | O6: ='mu-функции'!D43 -> 0 | P6: ='mu-функции'!F43 -> 0.4 | S6: =IF(OR(AND(J6>0,D6>0), AND(D6>0,I6>0,O6>0)), MAX(MAX(I6,J6),D6,O6),0) -> 0 | T6: =MAX(MIN(MAX(C6,D6),MAX(H6,I6)),MIN(N6,O6)) -> 0.5 | U6: =MIN(C6,MIN(MIN(G6,H6),M6,N6)) -> 0 | W6: =IF(OR(S6>U6,T6>U6),"принять","отказать") -> принять
A7: ='mu-функции'!A7 -> 185 | B7: ='mu-функции'!B7 -> 0 | C7: ='mu-функции'!C7 -> 0.75 | D7: ='mu-функции'!D7 -> 0 | E7: ='mu-функции'!F7 -> 0.3125 | G7: ='mu-функции'!A28 -> 50 | H7: ='mu-функции'!B28 -> 0 | I7: ='mu-функции'!C28 -> 1 | J7: ='mu-функции'!D28 -> 0 | K7: ='mu-функции'!F28 -> 0.5 | M7: ='mu-функции'!B44 -> 0 | N7: ='mu-функции'!C44 -> 1 | O7: ='mu-функции'!D44 -> 0 | P7: ='mu-функции'!F44 -> 0.5 | S7: =IF(OR(AND(J7>0,D7>0), AND(D7>0,I7>0,O7>0)), MAX(MAX(I7,J7),D7,O7),0) -> 0 | T7: =MAX(MIN(MAX(C7,D7),MAX(H7,I7)),MIN(N7,O7)) -> 0.75 | U7: =MIN(C7,MIN(MIN(G7,H7),M7,N7)) -> 0 | W7: =IF(OR(S7>U7,T7>U7),"принять","отказать") -> принять
A8: ='mu-функции'!A8 -> 190 | B8: ='mu-функции'!B8 -> 0 | C8: ='mu-функции'!C8 -> 1 | D8: ='mu-функции'!D8 -> 0 | E8: ='mu-функции'!F8 -> 0.375 | G8: ='mu-функции'!A29 -> 60 | H8: ='mu-функции'!B29 -> 0 | I8: ='mu-функции'!C29 -> 0.66666667 | J8: ='mu-функции'!D29 -> 0 | K8: ='mu-функции'!F29 -> 0.6 | M8: ='mu-функции'!B45 -> 0 | N8: ='mu-функции'!C45 -> 0.75 | O8: ='mu-функции'!D45 -> 0 | P8: ='mu-функции'!F45 -> 0.6 | S8: =IF(OR(AND(J8>0,D8>0), AND(D8>0,I8>0,O8>0)), MAX(MAX(I8,J8),D8,O8),0) -> 0 | T8: =MAX(MIN(MAX(C8,D8),MAX(H8,I8)),MIN(N8,O8)) -> 0.66666667 | U8: =MIN(C8,MIN(MIN(G8,H8),M8,N8)) -> 0 | W8: =IF(OR(S8>U8,T8>U8),"принять","отказать") -> принять
A9: ='mu-функции'!A9 -> 195 | B9: ='mu-функции'!B9 -> 0 | C9: ='mu-функции'!C9 -> 0.66666667 | D9: ='mu-функции'!D9 -> 0.1 | E9: ='mu-функции'!F9 -> 0.4375 | G9: ='mu-функции'!A30 -> 70 | H9: ='mu-функции'!B30 -> 0 | I9: ='mu-функции'!C30 -> 0.33333333 | J9: ='mu-функции'!D30 -> 0 | K9: ='mu-функции'!F30 -> 0.7 | M9: ='mu-функции'!B46 -> 0 | N9: ='mu-функции'!C46 -> 0.5 | O9: ='mu-функции'!D46 -> 0.25 | P9: ='mu-функции'!F46 -> 0.7 | S9: =IF(OR(AND(J9>0,D9>0), AND(D9>0,I9>0,O9>0)), MAX(MAX(I9,J9),D9,O9),0) -> 0.33333333 | T9: =MAX(MIN(MAX(C9,D9),MAX(H9,I9)),MIN(N9,O9)) -> 0.33333333 | U9: =MIN(C9,MIN(MIN(G9,H9),M9,N9)) -> 0 | W9: =IF(OR(S9>U9,T9>U9),"принять","отказать") -> принять
A10: ='mu-функции'!A10 -> 200 | B10: ='mu-функции'!B10 -> 0 | C10: ='mu-функции'!C10 -> 0.33333333 | D10: ='mu-функции'!D10 -> 0.2 | E10: ='mu-функции'!F10 -> 0.5 | G10: ='mu-функции'!A31 -> 80 | H10: ='mu-функции'!B31 -> 0 | I10: ='mu-функции'!C31 -> 0 | J10: ='mu-функции'!D31 -> 0.33333333 | K10: ='mu-функции'!F31 -> 0.8 | M10: ='mu-функции'!B47 -> 0 | N10: ='mu-функции'!C47 -> 0.25 | O10: ='mu-функции'!D47 -> 0.5 | P10: ='mu-функции'!F47 -> 0.8 | S10: =IF(OR(AND(J10>0,D10>0), AND(D10>0,I10>0,O10>0)), MAX(MAX(I10,J10),D10,O10),0) -> 0.5 | T10: =MAX(MIN(MAX(C10,D10),MAX(H10,I10)),MIN(N10,O10)) -> 0.25 | U10: =MIN(C10,MIN(MIN(G10,H10),M10,N10)) -> 0 | W10: =IF(OR(S10>U10,T10>U10),"принять","отказать") -> принять
A11: ='mu-функции'!A11 -> 205 | B11: ='mu-функции'!B11 -> 0 | C11: ='mu-функции'!C11 -> 0 | D11: ='mu-функции'!D11 -> 0.3 | E11: ='mu-функции'!F11 -> 0.5625 | G11: ='mu-функции'!A32 -> 90 | H11: ='mu-функции'!B32 -> 0 | I11: ='mu-функции'!C32 -> 0 | J11: ='mu-функции'!D32 -> 0.66666667 | K11: ='mu-функции'!F32 -> 0.9 | M11: ='mu-функции'!B48 -> 0 | N11: ='mu-функции'!C48 -> 0 | O11: ='mu-функции'!D48 -> 0.75 | P11: ='mu-функции'!F48 -> 0.9 | S11: =IF(OR(AND(J11>0,D11>0), AND(D11>0,I11>0,O11>0)), MAX(MAX(I11,J11),D11,O11),0) -> 0.75 | T11: =MAX(MIN(MAX(C11,D11),MAX(H11,I11)),MIN(N11,O11)) -> 0 | U11: =MIN(C11,MIN(MIN(G11,H11),M11,N11)) -> 0 | W11: =IF(OR(S11>U11,T11>U11),"принять","отказать") -> принять
A12: ='mu-функции'!A12 -> 210 | B12: ='mu-функции'!B12 -> 0 | C12: ='mu-функции'!C12 -> 0 | D12: ='mu-функции'!D12 -> 0.4 | E12: ='mu-функции'!F12 -> 0.625 | G12: ='mu-функции'!A33 -> 100 | H12: ='mu-функции'!B33 -> 0 | I12: ='mu-функции'!C33 -> 0 | J12: ='mu-функции'!D33 -> 1 | K12: ='mu-функции'!F33 -> 1 | M12: ='mu-функции'!B49 -> 0 | N12: ='mu-функции'!C49 -> 0 | O12: ='mu-функции'!D49 -> 1 | P12: ='mu-функции'!F49 -> 1 | S12: =IF(OR(AND(J12>0,D12>0), AND(D12>0,I12>0,O12>0)), MAX(MAX(I12,J12),D12,O12),0) -> 1 | T12: =MAX(MIN(MAX(C12,D12),MAX(H12,I12)),MIN(N12,O12)) -> 0 | U12: =MIN(C12,MIN(MIN(G12,H12),M12,N12)) -> 0 | W12: =IF(OR(S12>U12,T12>U12),"принять","отказать") -> принять
A13: ='mu-функции'!A13 -> 215 | B13: ='mu-функции'!B13 -> 0 | C13: ='mu-функции'!C13 -> 0 | D13: ='mu-функции'!D13 -> 0.5 | E13: ='mu-функции'!F13 -> 0.6875
A14: ='mu-функции'!A14 -> 220 | B14: ='mu-функции'!B14 -> 0 | C14: ='mu-функции'!C14 -> 0 | D14: ='mu-функции'!D14 -> 0.6 | E14: ='mu-функции'!F14 -> 0.75
A15: ='mu-функции'!A15 -> 225 | B15: ='mu-функции'!B15 -> 0 | C15: ='mu-функции'!C15 -> 0 | D15: ='mu-функции'!D15 -> 0.7 | E15: ='mu-функции'!F15 -> 0.8125
A16: ='mu-функции'!A16 -> 230 | B16: ='mu-функции'!B16 -> 0 | C16: ='mu-функции'!C16 -> 0 | D16: ='mu-функции'!D16 -> 0.8 | E16: ='mu-функции'!F16 -> 0.875
A17: ='mu-функции'!A17 -> 235 | B17: ='mu-функции'!B17 -> 0 | C17: ='mu-функции'!C17 -> 0 | D17: ='mu-функции'!D17 -> 0.9 | E17: ='mu-функции'!F17 -> 0.9375
A18: ='mu-функции'!A18 -> 240 | B18: ='mu-функции'!B18 -> 0 | C18: ='mu-функции'!C18 -> 0 | D18: ='mu-функции'!D18 -> 0.98 | E18: ='mu-функции'!F18 -> 1

Sheet Расчет кандидатовВ1
A1: Кандидат | B1: Рост | C1: Техника | D1: Результативность | E1: Решение/Уверенность | F1: Расчетный результат Рост | G1: Расчетный результат Техника | H1: Расчетный Результативность
A2: А | B2: 165 | C2: 20 | D2: 10 | E2: Отказ | F2: Низкий | G2: Слабая | H2: Низкая
A3: Б | B3: 180 | C3: 50 | D3: 50 | E3: Средняя | F3: Низкий | G3: Уверенная | H3: Высокая
A4: В | B4: 200 | C4: 80 | D4: 25 | E4: Средняя | F4: Средний | G4: Звезда | H4: Средняя
A5: Г | B5: 160 | C5: 80 | D5: 45 | E5: Абсолютная | F5: Низкий | G5: Звезда | H5: Высокая
A6: Д | B6: 245 | C6: 10 | D6: 35 | E6: Низкая | F6: Высокий | G6: Слабая | H6: Средняя
A7: Е | B7: 250 | C7: 90 | D7: 45 | E7: Абсолютная | F7: Высокий | G7: Звезда | H7: Высокая

Sheet Лист1
A1: Рост | B1: Низкий (B) | C1: Низкий2 (A)
A2: 160 | B2: 1 | C2: 1
A3: 165 | B3: 0.8 | C3: 0.8
A4: 170 | B4: 0.6 | C4: 0.6
A5: 175 | B5: 0.4 | C5: 0.5
A6: 180 | B6: 0.2 | C6: 0 | D6: 0.8
A7: 185 | B7: 0 | C7: 0
A8: 190 | B8: 0 | C8: 0
A9: 195 | B9: 0 | C9: 0
A10: 200 | B10: 0 | C10: 0
A11: 205 | B11: 0 | C11: 0
A12: 210 | B12: 0 | C12: 0
A13: 215 | B13: 0 | C13: 0
A14: 220 | B14: 0 | C14: 0
A15: 225 | B15: 0 | C15: 0
A16: 230 | B16: 0 | C16: 0
A17: 235 | B17: 0 | C17: 0
A18: 240 | B18: 0 | C18: 0
